import os
import re
import sys

import pandas as pd
from utility import read_params, create_directory_path, values_from_schema_function, \
    get_logger_object_of_prediction, get_date, get_time
import argparse
import shutil

from insurance_exception.insurance_exception import InsuranceException as GenericException

log_collection_name = "data_validator"


class DataValidator:
    def __init__(self, config, logger, is_logging_enable=True):
        try:
            self.logger = logger
            self.logger.is_log_enable = is_logging_enable
            self.config = config
            self.file_path = self.config['data_source']['Prediction_Batch_Files']
            self.good_file_path = self.config['artifacts']['prediction_data']['good_file_path']
            self.bad_file_path = self.config['artifacts']['prediction_data']['bad_file_path']
            self.archive_bad_file_path = self.config['artifacts']['prediction_data']['archive_bad_file_path']
            self.prediction_schema_file = self.config['config']['schema_prediction']
        except Exception as e:
            generic_exception = GenericException(
                "Error occurred in module [{0}] class [{1}] method [{2}]"
                    .format(self.__module__, DataValidator.__name__,
                            self.__init__.__name__))
            raise Exception(generic_exception.error_message_detail(str(e), sys)) from e

    def archive_bad_files(self):
        try:
            folder_name=f"bad_files_{get_date().replace('-','_')}_{get_time().replace(':','_')}"
            archive_directory_path=os.path.join(self.archive_bad_file_path,folder_name)
            create_directory_path(archive_directory_path)
            for file in os.listdir(self.bad_file_path):
                source_file_path=os.path.join(self.bad_file_path,file)
                shutil.move(source_file_path,archive_directory_path)
        except Exception as e:
            generic_exception = GenericException(
                "Error occurred in module [{0}] class [{1}] method [{2}]"
                    .format(self.__module__, DataValidator.__name__,
                            self.archive_bad_files.__name__))
            raise Exception(generic_exception.error_message_detail(str(e), sys)) from e


    def create_good_bad_archive_bad_file_path(self):
        try:
            create_directory_path(self.good_file_path)
            create_directory_path(self.bad_file_path)
            create_directory_path(self.archive_bad_file_path,is_recreate=False)
        except Exception as e:

            generic_exception = GenericException(
                "Error occurred in module [{0}] class [{1}] method [{2}]"
                    .format(self.__module__, DataValidator.__name__,
                            self.create_good_bad_archive_bad_file_path.__name__))
            raise Exception(generic_exception.error_message_detail(str(e), sys)) from e


    def value_from_schema(self):
        """

        :return: tuple (sample_file_name,column_names,number_of_column)
        """
        try:
            return values_from_schema_function(self.prediction_schema_file)
        except Exception as e:
            generic_exception = GenericException(
                "Error occurred in module [{0}] class [{1}] method [{2}]"
                    .format(self.__module__, DataValidator.__name__,
                            self.value_from_schema.__name__))
            raise Exception(generic_exception.error_message_detail(str(e), sys)) from e


    def file_name_regular_expression(self):
        """

        :return: regular expression syntax which can be used for validation of file name
        """
        return "['HealthPrem']+['\_'']+[\d_]+[\d]+\.csv"

    def validate_missing_values_in_whole_column(self):
        try:
            self.logger.log("Missing Values Validation Started!!")
            for file in os.listdir(self.good_file_path):
                csv = pd.read_csv(os.path.join(self.good_file_path, file))
                count = 0
                for columns in csv:
                    if (len(csv[columns]) - csv[columns].count()) == len(csv[columns]):
                        count += 1
                        shutil.move(os.path.join(self.good_file_path, file),
                                    self.bad_file_path)
                        self.logger.log(
                            "Invalid Column Length for the file!! File moved to Bad Raw Folder :: %s" % file)
                        break
                if count == 0:
                    print(csv.columns)
                    csv.rename(columns={"Unnamed: 0": "Premium "}, inplace=True)
                    csv.to_csv(os.path.join(self.good_file_path, file), index=None, header=True)
        except Exception as e:
            generic_exception = GenericException(
                "Error occurred in module [{0}] class [{1}] method [{2}]"
                    .format(self.__module__, DataValidator.__name__,
                            self.validate_missing_values_in_whole_column.__name__))
            raise Exception(generic_exception.error_message_detail(str(e), sys)) from e


    def validate_file_name(self):
        try:
            self.create_good_bad_archive_bad_file_path()
            pattern, length_of_date_stamp_in_file, length_of_time_stamp_in_file, column_names, number_of_columns = self.value_from_schema()

            file_name_reg_pattern = self.file_name_regular_expression()
            self.logger.log(f"Validating file names.")
            files = os.listdir(self.file_path)
            for file in files:
                file_path = os.path.join(self.file_path, file)
                split_at_dot = re.split('.csv', file)
                split_at_dot = (re.split('_', split_at_dot[0]))
                if re.match(file_name_reg_pattern, file) and len(split_at_dot[1]) == length_of_date_stamp_in_file \
                        and len(split_at_dot[2]) == length_of_time_stamp_in_file:
                    destination_file_path = os.path.join(self.good_file_path, file)
                    self.logger.log(f"file name : {file} matched hence moving file to good file path {destination_file_path}")
                    shutil.move(file_path, destination_file_path)
                else:
                    destination_file_path = os.path.join(self.bad_file_path, file)
                    self.logger.log(f"file name: {file} does not matched hence moving file to bad file path {destination_file_path}")
                    shutil.move(file_path, destination_file_path)
        except Exception as e:
            generic_exception = GenericException(
                "Error occurred in module [{0}] class [{1}] method [{2}]"
                    .format(self.__module__, DataValidator.__name__,
                            self.validate_file_name.__name__))
            raise Exception(generic_exception.error_message_detail(str(e), sys)) from e


    def validate_no_of_column(self, no_of_column):
        """
        Description:
        If number of column matches then file will be move to good file path else bad file path
        =====================================================================================
        :param no_of_column: int Number of column must present in each file
        :return: Nothing
        """
        try:
            self.logger.log(f"Validating number of column in input file")
            files = os.listdir(self.good_file_path)
            for file in files:
                file_path = os.path.join(self.good_file_path, file)
                df = pd.read_csv(file_path)
                if df.shape[1] != no_of_column:
                    destination_file_path = os.path.join(self.bad_file_path, file)
                    self.logger.log(f"file: {file} has incorrect number of column hence moving file to bad file path {destination_file_path}")
                    shutil.move(file_path, destination_file_path)
        except Exception as e:
            generic_exception = GenericException(
                "Error occurred in module [{0}] class [{1}] method [{2}]"
                    .format(self.__module__, DataValidator.__name__,
                            self.validate_no_of_column.__name__))
            raise Exception(generic_exception.error_message_detail(str(e), sys)) from e


def validation_main(config_path: str, datasource: str, is_logging_enable=True,execution_id=None,executed_by=None) -> None:
    try:
        logger = get_logger_object_of_prediction(config_path=config_path, collection_name=log_collection_name,
                                                 execution_id=execution_id, executed_by=executed_by)

        logger.is_log_enable = is_logging_enable
        config = read_params(config_path)
        logger.log("data validation started")
        data_validator = DataValidator(config=config, logger=logger, is_logging_enable=is_logging_enable)
        pattern, length_of_date_stamp_in_file, length_of_time_stamp_in_file, column_names, number_of_columns = \
            data_validator.value_from_schema()
        data_validator.validate_file_name()
        data_validator.validate_no_of_column(no_of_column=number_of_columns)
        data_validator.validate_missing_values_in_whole_column()
        data_validator.archive_bad_files()
    except Exception as e:
        generic_exception = GenericException(
            "Error occurred in module [{0}] method [{1}]"
                .format(validation_main.__module__,
                        validation_main.__name__))
        raise Exception(generic_exception.error_message_detail(str(e), sys)) from e


if __name__ == '__main__':
    args = argparse.ArgumentParser()
    args.add_argument("--config", default=os.path.join("config", "params.yaml"))
    args.add_argument("--datasource", default=None)
    parsed_args = args.parse_args()
    print("started")
    validation_main(config_path=parsed_args.config, datasource=parsed_args.datasource)
